Workbook

Sheet splits v3
B1: Name | C1: Bib Number | D1: Gender | E1: AS1 arr order | F1: AS1 arr TOD | G1: AS1 dep TOD | H1: AS2 arr order | I1: AS2 arr TOD | J1: AS2dep TOD | K1: AS3 arr order | L1: AS3 arr TOD | M1: AS3 dep TOD | N1: AS4 arr order | O1: AS4 arr TOD | P1: AS4 dep TOD | Q1: AS5 arr order | R1: AS5 arr TOD | S1: AS5 dep TOD | T1: AS6 arr order | U1: AS6 arr TOD | V1: AS6 dep TOD | W1: AS7 arr order | X1: AS7 arr TOD | Y1: AS7 dep TOD | Z1: AS8 arr order | AA1: AS8 arr TOD | AB1: AS8 dep TOD | AC1: AS9 arr order | AD1: AS9 arr TOD | AE1: AS9 dep TOD | AF1: AS10 arr order | AG1: AS10 arr TOD | AH1: AS10 dep TOD | AI1: AS11 arr order | AJ1: AS11 arr TOD | AK1: AS11 dep TOD | AL1: AS12 arr order | AM1: AS12 arr TOD | AN1: AS12 dep TOD | AO1: AS13 arr order | AP1: AS13 arr TOD | AQ1: AS13 dep TOD | AR1: AS14 arr order | AS1: AS14 arr TOD | AT1: AS14 dep TOD | AU1: AS15 arr order | AV1: AS15 arr TOD | AW1: AS15 dep TOD | AX1: AS16 arr order | AY1: AS16 arr TOD | AZ1: AS16 dep TOD | BA1: F arr order | BB1: F arr TOD
B2: RYAN CLIFFORD | C2: 537 | D2: M | E2: 1 | F2: 0.25138889 | G2: 0.25208333 | H2: 9 | I2: 0.29444444 | J2: 0.29444444 | K2: 3 | L2: 0.34097222 | M2: 0.34236111 | N2: 1 | O2: 0.39513889 | P2: 0.39583333 | Q2: 1 | R2: 0.43680556 | S2: 0.43680556 | T2: 1 | U2: 0.47708333 | V2: 0.47847222 | W2: 1 | X2: 0.50972222 | Y2: 0.51111111 | Z2: 1 | AB2: 0.57430556 | AC2: 1 | AD2: 0.61527778 | AE2: 0.61666667 | AF2: 1 | AG2: 0.67916667 | AH2: 0.68333333 | AI2: 1 | AJ2: 0.72777778 | AK2: 0.72847222 | AL2: 1 | AM2: 0.78680556 | AN2: 0.78958333 | AO2: 1 | AP2: 0.82291667 | AQ2: 0.82708333 | AR2: 1 | AS2: 0.87361111 | AT2: 0.875 | AU2: 1 | AV2: 0.94583333 | AW2: 0.95 | AX2: 1 | AY2: 0.0048611111 | AZ2: 0.0076388889 | BA2: 1 | BB2: 44787.051
B3: EMANUEL KING | C3: 596 | D3: M | E3: 3 | F3: 0.25138889 | G3: 0.25208333 | H3: 1 | I3: 0.29097222 | J3: 0.29166667 | K3: 2 | L3: 0.34097222 | M3: 0.34305556 | N3: 2 | O3: 0.40069444 | P3: 0.40138889 | Q3: 2 | R3: 0.44722222 | S3: 0.44930556 | T3: 2 | U3: 0.50763889 | V3: 0.50902778 | W3: 2 | X3: 0.54097222 | Y3: 0.54305556 | Z3: 2 | AB3: 0.62291667 | AC3: 2 | AD3: 0.66736111 | AE3: 0.67013889 | AF3: 2 | AG3: 0.73958333 | AH3: 0.74583333 | AI3: 2 | AJ3: 0.8 | AK3: 0.80138889 | AL3: 2 | AM3: 0.87152778 | AN3: 0.87361111 | AO3: 2 | AP3: 0.91527778 | AQ3: 0.92013889 | AR3: 2 | AS3: 0.97430556 | AT3: 0.97777778 | AU3: 2 | AV3: 0.056944444 | AW3: 0.060416667 | AX3: 2 | AY3: 0.11875 | AZ3: 0.11944444 | BA3: 2 | BB3: 44787.158
B4: TRISTAN BAXENDALE | C4: 513 | D4: M | E4: 9 | F4: 0.25208333 | G4: 0.25277778 | H4: 7 | I4: 0.29236111 | J4: 0.29236111 | K4: 9 | L4: 0.34583333 | M4: 0.34791667 | N4: 8 | O4: 0.41666667 | P4: 0.41875 | Q4: 8 | R4: 0.47291667 | S4: 0.47430556 | T4: 10 | U4: 0.53055556 | V4: 0.53263889 | W4: 12 | X4: 0.57430556 | Y4: 0.57777778 | Z4: 9 | AB4: 0.65902778 | AC4: 8 | AD4: 0.70625 | AE4: 0.70972222 | AF4: 8 | AG4: 0.78333333 | AH4: 0.78680556 | AI4: 7 | AJ4: 0.84097222 | AK4: 0.84375 | AL4: 5 | AM4: 0.91180556 | AN4: 0.91736111 | AO4: 6 | AP4: 0.96319444 | AQ4: 0.96666667 | AR4: 4 | AS4: 0.020138889 | AT4: 0.023611111 | AU4: 4 | AV4: 0.10625 | AW4: 0.11041667 | AX4: 3 | AY4: 0.16388889 | AZ4: 0.16458333 | BA4: 3 | BB4: 44787.199
B5: ERIC KOSEK | C5: 603 | D5: M | E5: 6 | F5: 0.25208333 | G5: 0.25277778 | H5: 6 | I5: 0.29236111 | J5: 0.29236111 | K5: 8 | L5: 0.34583333 | M5: 0.34791667 | N5: 9 | O5: 0.41666667 | P5: 0.41875 | Q5: 9 | R5: 0.47291667 | S5: 0.475 | T5: 8 | U5: 0.52291667 | V5: 0.525 | W5: 8 | X5: 0.55902778 | Y5: 0.56319444 | Z5: 7 | AB5: 0.64652778 | AC5: 7 | AD5: 0.70069444 | AE5: 0.70694444 | AF5: 7 | AG5: 0.78333333 | AH5: 0.79305556 | AI5: 8 | AJ5: 0.84861111 | AK5: 0.85347222 | AL5: 7 | AM5: 0.92430556 | AN5: 0.92708333 | AO5: 7 | AP5: 0.97222222 | AQ5: 0.97708333 | AR5: 6 | AS5: 0.034722222 | AT5: 0.038888889 | AU5: 6 | AV5: 0.12361111 | AW5: 0.12638889 | AX5: 6 | AY5: 0.17777778 | AZ5: 0.17777778 | BA5: 4 | BB5: 44787.207
B6: KEVIN SCOTT | C6: 689 | D6: M | E6: 12 | F6: 0.25416667 | G6: 0.25416667 | K6: 13 | L6: 0.35555556 | M6: 0.35902778 | N6: 14 | O6: 0.42847222 | P6: 0.42916667 | Q6: 14 | R6: 0.48958333 | S6: 0.49097222 | T6: 13 | U6: 0.54375 | V6: 0.54444444 | W6: 13 | X6: 0.57916667 | Y6: 0.58680556 | Z6: 10 | AB6: 0.67013889 | AC6: 10 | AD6: 0.71736111 | AE6: 0.71944444 | AF6: 9 | AG6: 0.79166667 | AH6: 0.79930556 | AI6: 9 | AJ6: 0.85416667 | AK6: 0.85763889 | AL6: 6 | AM6: 0.92291667 | AN6: 0.925 | AO6: 5 | AP6: 0.9625 | AQ6: 0.96805556 | AR6: 5 | AS6: 0.022222222 | AT6: 0.025694444 | AU6: 5 | AV6: 0.10694444 | AW6: 0.1125 | AX6: 5 | AY6: 0.17638889 | AZ6: 0.17708333 | BA6: 5 | BB6: 44787.213
B7: BENJAMIN LINNE | C7: 620 | D7: M | E7: 10 | F7: 0.25208333 | G7: 0.25277778 | H7: 8 | I7: 0.29236111 | J7: 0.29236111 | K7: 6 | L7: 0.34444444 | M7: 0.34652778 | N7: 7 | O7: 0.41597222 | P7: 0.41666667 | Q7: 7 | R7: 0.47083333 | S7: 0.47222222 | T7: 7 | U7: 0.51944444 | V7: 0.52083333 | W7: 7 | X7: 0.55277778 | Y7: 0.55763889 | Z7: 6 | AB7: 0.64305556 | AC7: 5 | AD7: 0.69166667 | AE7: 0.69375 | AF7: 5 | AG7: 0.76736111 | AH7: 0.77013889 | AI7: 4 | AJ7: 0.82569444 | AK7: 0.82708333 | AL7: 4 | AM7: 0.90277778 | AN7: 0.90486111 | AO7: 3 | AP7: 0.94652778 | AQ7: 0.95069444 | AR7: 3 | AS7: 0.0076388889 | AT7: 0.011111111 | AU7: 3 | AV7: 0.10277778 | AW7: 0.10555556 | AX7: 4 | AY7: 0.17291667 | AZ7: 0.17361111 | BA7: 6 | BB7: 44787.217
B8: NICOLAS CROUZIER | C8: 543 | D8: M | E8: 26 | F8: 0.25972222 | G8: 0.26041667 | K8: 24 | L8: 0.36388889 | M8: 0.36736111 | N8: 19 | O8: 0.43541667 | P8: 0.4375 | Q8: 16 | R8: 0.49236111 | S8: 0.49513889 | T8: 16 | U8: 0.54861111 | V8: 0.55138889 | W8: 16 | X8: 0.59097222 | Y8: 0.60208333 | Z8: 17 | AB8: 0.69097222 | AC8: 14 | AD8: 0.74027778 | AE8: 0.74305556 | AF8: 12 | AG8: 0.81597222 | AH8: 0.82430556 | AI8: 12 | AJ8: 0.875 | AK8: 0.88055556 | AL8: 10 | AM8: 0.94652778 | AN8: 0.95208333 | AO8: 9 | AP8: 0.99097222 | AQ8: 0.99583333 | AR8: 8 | AS8: 0.049305556 | AT8: 0.052083333 | AU8: 7 | AV8: 0.13888889 | AW8: 0.14236111 | AX8: 7 | AY8: 0.25833333 | AZ8: 0.21875 | BA8: 7 | BB8: 44787.267
B9: ANTHONY BECKER | C9: 515 | D9: M | E9: 16 | F9: 0.25694444 | G9: 0.25694444 | H9: 16 | I9: 0.30208333 | J9: 0.30208333 | K9: 14 | L9: 0.35902778 | M9: 0.35972222 | N9: 13 | O9: 0.42777778 | P9: 0.42847222 | Q9: 12 | R9: 0.48263889 | S9: 0.48333333 | T9: 12 | U9: 0.53402778 | V9: 0.53472222 | W9: 9 | X9: 0.57013889 | Y9: 0.57152778 | Z9: 8 | AB9: 0.65902778 | AC9: 9 | AD9: 0.71319444 | AE9: 0.71458333 | AF9: 10 | AG9: 0.79305556 | AH9: 0.79444444 | AI9: 10 | AJ9: 0.85555556 | AK9: 0.85763889 | AL9: 9 | AM9: 0.93819444 | AN9: 0.94027778 | AO9: 10 | AP9: 0.99236111 | AQ9: 0.99444444 | AR9: 10 | AS9: 0.056944444 | AT9: 0.059027778 | AU9: 9 | AV9: 0.15416667 | AW9: 0.15625 | AX9: 8 | AY9: 0.225 | AZ9: 0.22638889 | BA9: 8 | BB9: 44787.268
B10: CALEB ROTH | C10: 685 | D10: M | E10: 31 | F10: 0.25972222 | G10: 0.26041667 | H10: 33 | I10: 0.30902778 | J10: 0.30902778 | K10: 33 | L10: 0.36875 | M10: 0.37083333 | N10: 29 | O10: 0.44513889 | P10: 0.44583333 | Q10: 26 | R10: 0.50208333 | S10: 0.50416667 | T10: 28 | U10: 0.56180556 | V10: 0.56319444 | W10: 28 | X10: 0.60277778 | Y10: 0.60625 | Z10: 22 | AB10: 0.69652778 | AC10: 21 | AD10: 0.74861111 | AE10: 0.75347222 | AF10: 19 | AG10: 0.82916667 | AH10: 0.83541667 | AI10: 17 | AJ10: 0.89583333 | AK10: 0.89930556 | AL10: 14 | AM10: 0.96736111 | AN10: 0.97152778 | AO10: 11 | AP10: 0.0125 | AQ10: 0.015277778 | AR10: 11 | AS10: 0.072222222 | AT10: 0.076388889 | AU10: 10 | AV10: 0.16597222 | AW10: 0.16944444 | AX10: 10 | AY10: 0.24097222 | AZ10: 0.24236111 | BA10: 9 | BB10: 44787.283
B11: TREVOR FYE | C11: 563 | D11: M | E11: 7 | F11: 0.25208333 | G11: 0.25277778 | K11: 7 | L11: 0.34583333 | M11: 0.34791667 | N11: 6 | O11: 0.41597222 | P11: 0.41666667 | Q11: 6 | R11: 0.47083333 | S11: 0.47222222 | T11: 5 | U11: 0.51805556 | V11: 0.51944444 | W11: 6 | X11: 0.55277778 | Y11: 0.55555556 | Z11: 5 | AB11: 0.64166667 | AC11: 6 | AD11: 0.69166667 | AE11: 0.69375 | AF11: 6 | AG11: 0.77152778 | AH11: 0.775 | AI11: 6 | AJ11: 0.83958333 | AK11: 0.84166667 | AL11: 8 | AM11: 0.92986111 | AN11: 0.93263889 | AO11: 8 | AP11: 0.98680556 | AQ11: 0.98958333 | AR11: 9 | AS11: 0.050694444 | AT11: 0.052083333 | AU11: 8 | AV11: 0.15277778 | AW11: 0.15694444 | AX11: 9 | AY11: 0.2375 | AZ11: 0.23819444 | BA11: 10 | BB11: 44787.285
B12: ADAM KOLB | C12: 601 | D12: M | E12: 11 | F12: 0.25416667 | G12: 0.25416667 | H12: 12 | I12: 0.29861111 | J12: 0.29861111 | K12: 15 | L12: 0.35902778 | M12: 0.36180556 | N12: 22 | O12: 0.43680556 | P12: 0.43819444 | Q12: 20 | R12: 0.49583333 | S12: 0.49791667 | T12: 20 | U12: 0.55347222 | V12: 0.55555556 | W12: 19 | X12: 0.59305556 | Y12: 0.59791667 | Z12: 19 | AB12: 0.69236111 | AC12: 19 | AD12: 0.74513889 | AE12: 0.74722222 | AF12: 16 | AG12: 0.82291667 | AH12: 0.82777778 | AI12: 15 | AJ12: 0.88819444 | AK12: 0.88958333 | AL12: 16 | AM12: 0.96944444 | AN12: 0.97222222 | AO12: 13 | AP12: 0.021527778 | AQ12: 0.027083333 | AR12: 13 | AS12: 0.089583333 | AT12: 0.093055556 | AU12: 13 | AV12: 0.18402778 | AW12: 0.18888889 | AX12: 12 | AY12: 0.25138889 | AZ12: 0.25138889 | BA12: 11 | BB12: 44787.286
B13: JUSTYNA WILSON | C13: 731 | D13: F | E13: 24 | F13: 0.25902778 | G13: 0.25972222 | H13: 136 | I13: 0.33402778 | J13: 0.33402778 | K13: 30 | L13: 0.36736111 | M13: 0.36875 | N13: 25 | O13: 0.44166667 | P13: 0.44236111 | Q13: 25 | R13: 0.5 | S13: 0.50138889 | T13: 22 | U13: 0.55555556 | V13: 0.55625 | W13: 20 | X13: 0.59305556 | Y13: 0.59444444 | Z13: 13 | AB13: 0.68541667 | AC13: 12 | AD13: 0.73680556 | AE13: 0.7375 | AF13: 13 | AG13: 0.81666667 | AH13: 0.81875 | AI13: 13 | AJ13: 0.875 | AK13: 0.87708333 | AL13: 12 | AM13: 0.96180556 | AN13: 0.96388889 | AO13: 12 | AP13: 0.013888889 | AQ13: 0.015972222 | AR13: 12 | AS13: 0.08125 | AT13: 0.083333333 | AU13: 12 | AV13: 0.17986111 | AW13: 0.18263889 | AX13: 11 | AY13: 0.25138889 | AZ13: 0.25138889 | BA13: 12 | BB13: 44787.295
B14: ADAM KOPPANY | C14: 602 | D14: M | E14: 101 | F14: 0.26875 | G14: 0.26944444 | H14: 82 | I14: 0.32152778 | J14: 0.32152778 | K14: 60 | L14: 0.38194444 | M14: 0.38472222 | N14: 47 | O14: 0.45555556 | P14: 0.45694444 | Q14: 40 | R14: 0.5125 | S14: 0.51458333 | T14: 35 | U14: 0.56666667 | V14: 0.57013889 | W14: 34 | X14: 0.60972222 | Y14: 0.61319444 | Z14: 25 | AB14: 0.69930556 | AC14: 24 | AD14: 0.74930556 | AE14: 0.75208333 | AF14: 23 | AG14: 0.83055556 | AH14: 0.84236111 | AI14: 20 | AJ14: 0.90138889 | AK14: 0.90416667 | AL14: 18 | AM14: 0.97916667 | AN14: 0.98194444 | AO14: 17 | AP14: 0.03125 | AQ14: 0.034722222 | AR14: 15 | AS14: 0.096527778 | AT14: 0.10069444 | AU14: 14 | AV14: 0.19375 | AW14: 0.19583333 | AX14: 13 | AY14: 0.26111111 | AZ14: 0.25763889 | BA14: 13 | BB14: 44787.302
B15: JUSTIN LEWANDOWSKI | C15: 618 | D15: M | E15: 8 | F15: 0.25208333 | G15: 0.25277778 | H15: 5 | I15: 0.29236111 | J15: 0.29305556 | K15: 4 | L15: 0.34375 | M15: 0.34513889 | N15: 4 | O15: 0.41111111 | P15: 0.41319444 | Q15: 4 | R15: 0.46319444 | S15: 0.46527778 | T15: 3 | U15: 0.51180556 | V15: 0.51319444 | W15: 3 | X15: 0.55 | Y15: 0.55208333 | Z15: 3 | AB15: 0.63055556 | AC15: 3 | AD15: 0.675 | AE15: 0.67847222 | AF15: 3 | AG15: 0.75486111 | AH15: 0.76319444 | AI15: 3 | AJ15: 0.82083333 | AK15: 0.82430556 | AL15: 3 | AM15: 0.90069444 | AN15: 0.90694444 | AO15: 4 | AP15: 0.95833333 | AQ15: 0.96527778 | AR15: 7 | AS15: 0.0375 | AT15: 0.05 | AU15: 11 | AV15: 0.17430556 | AW15: 0.17708333 | AX15: 14 | AY15: 0.26180556 | AZ15: 0.26527778 | BA15: 14 | BB15: 44787.319
B16: ANDREW FOERSTER | C16: 561 | D16: M | E16: 36 | F16: 0.26041667 | G16: 0.26180556 | K16: 38 | L16: 0.37152778 | M16: 0.37708333 | N16: 32 | O16: 0.44583333 | P16: 0.44722222 | Q16: 31 | R16: 0.50347222 | S16: 0.50486111 | T16: 29 | U16: 0.56388889 | V16: 0.56597222 | W16: 31 | X16: 0.60625 | Y16: 0.61041667 | Z16: 21 | AB16: 0.69583333 | AC16: 23 | AD16: 0.74930556 | AE16: 0.75208333 | AF16: 18 | AG16: 0.82916667 | AH16: 0.83888889 | AI16: 19 | AJ16: 0.89861111 | AK16: 0.90069444 | AL16: 17 | AM16: 0.97708333 | AN16: 0.98055556 | AO16: 15 | AP16: 0.027777778 | AQ16: 0.031944444 | AR16: 16 | AS16: 0.097916667 | AT16: 0.10625 | AU16: 15 | AV16: 0.19444444 | AW16: 0.19583333 | AX16: 15 | AY16: 0.26527778 | AZ16: 0.26666667 | BA16: 15 | BB16: 44787.32
B17: STEVE CAMPBELL | C17: 529 | D17: M | E17: 71 | F17: 0.26388889 | G17: 0.26458333 | H17: 65 | I17: 0.31875 | J17: 0.31875 | K17: 58 | L17: 0.37916667 | M17: 0.38125 | N17: 39 | O17: 0.45 | P17: 0.45069444 | Q17: 38 | R17: 0.50972222 | S17: 0.51111111 | T17: 31 | U17: 0.56527778 | V17: 0.56666667 | W17: 29 | X17: 0.60277778 | Y17: 0.60625 | Z17: 20 | AB17: 0.69513889 | AC17: 18 | AD17: 0.74444444 | AE17: 0.74583333 | AF17: 15 | AG17: 0.82291667 | AH17: 0.82638889 | AI17: 14 | AJ17: 0.88541667 | AK17: 0.88680556 | AL17: 15 | AM17: 0.96875 | AN17: 0.97222222 | AO17: 14 | AP17: 0.024305556 | AQ17: 0.027083333 | AR17: 14 | AS17: 0.095138889 | AT17: 0.097916667 | AU17: 16 | AV17: 0.19930556 | AW17: 0.20138889 | AX17: 16 | AY17: 0.27777778 | AZ17: 0.27847222 | BA17: 16 | BB17: 44787.324
B18: BARRY MAIN | C18: 629 | D18: M | E18: 29 | F18: 0.25972222 | G18: 0.26041667 | H18: 27 | I18: 0.30694444 | J18: 0.30694444 | K18: 19 | L18: 0.3625 | M18: 0.36527778 | N18: 17 | O18: 0.43472222 | P18: 0.43680556 | Q18: 17 | R18: 0.49305556 | S18: 0.49652778 | T18: 18 | U18: 0.55069444 | V18: 0.55416667 | W18: 15 | X18: 0.59027778 | Y18: 0.59583333 | Z18: 18 | AB18: 0.69166667 | AC18: 20 | AD18: 0.74652778 | AE18: 0.75069444 | AF18: 17 | AG18: 0.82708333 | AH18: 0.83888889 | AI18: 18 | AJ18: 0.89861111 | AK18: 0.89861111 | AL18: 19 | AM18: 0.98263889 | AN18: 0.98819444 | AO18: 18 | AP18: 0.0375 | AQ18: 0.047222222 | AR18: 17 | AS18: 0.10833333 | AT18: 0.11458333 | AU18: 17 | AV18: 0.20972222 | AW18: 0.21736111 | AX18: 17 | AY18: 0.28611111 | AZ18: 0.28611111 | BA18: 17 | BB18: 44787.325
B19: MICHAEL OBARA | C19: 655 | D19: M | E19: 54 | F19: 0.26319444 | G19: 0.26388889 | H19: 43 | I19: 0.31388889 | J19: 0.31388889 | K19: 40 | L19: 0.37152778 | M19: 0.37569444 | N19: 31 | O19: 0.44583333 | P19: 0.44722222 | Q19: 27 | R19: 0.50208333 | S19: 0.50416667 | T19: 27 | U19: 0.56041667 | V19: 0.5625 | W19: 26 | X19: 0.60208333 | Y19: 0.60972222 | Z19: 26 | AB19: 0.69930556 | AC19: 22 | AD19: 0.74861111 | AE19: 0.75347222 | AF19: 21 | AG19: 0.83055556 | AH19: 0.84375 | AI19: 21 | AJ19: 0.90208333 | AK19: 0.90486111 | AL19: 20 | AM19: 0.99027778 | AN19: 0.99305556 | AO19: 19 | AP19: 0.049305556 | AQ19: 0.059722222 | AR19: 19 | AS19: 0.12361111 | AT19: 0.12777778 | AU19: 19 | AV19: 0.23194444 | AW19: 0.23819444 | AX19: 18 | AY19: 0.30625 | AZ19: 0.30625 | BA19: 18 | BB19: 44787.355
B20: SCOTT GLEASON | C20: 567 | D20: M | E20: 4 | F20: 0.25138889 | G20: 0.25208333 | K20: 5 | L20: 0.34375 | M20: 0.34513889 | N20: 12 | O20: 0.42430556 | P20: 0.42569444 | Q20: 18 | R20: 0.49444444 | S20: 0.49722222 | T20: 17 | U20: 0.55 | V20: 0.55208333 | W20: 21 | X20: 0.59652778 | Y20: 0.60277778 | Z20: 36 | AB20: 0.71597222 | AC20: 38 | AD20: 0.78125 | AE20: 0.78333333 | AF20: 41 | AG20: 0.87777778 | AH20: 0.88125 | AI20: 33 | AJ20: 0.94097222 | AK20: 0.94305556 | AL20: 29 | AM20: 0.03125 | AN20: 0.034722222 | AO20: 25 | AP20: 0.086111111 | AQ20: 0.090972222 | AR20: 24 | AS20: 0.15138889 | AT20: 0.15416667 | AU20: 21 | AV20: 0.24444444 | AW20: 0.24722222 | AX20: 19 | AY20: 0.31319444 | AZ20: 0.31388889 | BA20: 19 | BB20: 44787.358
B21: ADRIAN SPENCER | C21: 702 | D21: M | E21: 27 | F21: 0.25972222 | G21: 0.26041667 | H21: 23 | I21: 0.30625 | J21: 0.30625 | K21: 23 | L21: 0.36388889 | M21: 0.36736111 | N21: 20 | O21: 0.43541667 | P21: 0.4375 | Q21: 15 | R21: 0.49166667 | S21: 0.49513889 | T21: 15 | U21: 0.54861111 | V21: 0.55138889 | W21: 17 | X21: 0.59097222 | Y21: 0.60277778 | Z21: 16 | AB21: 0.69027778 | AC21: 15 | AD21: 0.74027778 | AE21: 0.74305556 | AF21: 11 | AG21: 0.81527778 | AH21: 0.81875 | AI21: 11 | AJ21: 0.875 | AK21: 0.875 | AL21: 11 | AM21: 0.96180556 | AN21: 0.96527778 | AO21: 16 | AP21: 0.029166667 | AQ21: 0.049305556 | AR21: 18 | AS21: 0.12083333 | AT21: 0.12430556 | AU21: 18 | AV21: 0.23125 | AW21: 0.23611111 | AX21: 20 | AY21: 0.31944444 | AZ21: 0.31944444 | BA21: 20 | BB21: 44787.363
B22: CHAD KAMPHUIS | C22: 591 | D22: M | E22: 169 | F22: 0.27430556 | G22: 0.275 | H22: 143 | I22: 0.33680556 | J22: 0.33680556 | K22: 110 | L22: 0.4 | M22: 0.40972222 | N22: 94 | O22: 0.48472222 | P22: 0.48611111 | Q22: 79 | R22: 0.54722222 | S22: 0.55 | T22: 67 | U22: 0.60694444 | V22: 0.60833333 | W22: 63 | X22: 0.64722222 | Y22: 0.65486111 | Z22: 52 | AB22: 0.74513889 | AC22: 48 | AD22: 0.79583333 | AE22: 0.79791667 | AF22: 37 | AG22: 0.87152778 | AH22: 0.87708333 | AI22: 31 | AJ22: 0.93958333 | AK22: 0.94236111 | AL22: 30 | AM22: 0.034722222 | AN22: 0.038194444 | AO22: 26 | AP22: 0.086111111 | AQ22: 0.093055556 | AR22: 26 | AS22: 0.15902778 | AT22: 0.16666667 | AU22: 24 | AV22: 0.25972222 | AW22: 0.26458333 | AX22: 22 | AY22: 0.32708333 | AZ22: 0.32777778 | BA22: 21 | BB22: 44787.372
B23: NICOLE WERNER | C23: 728 | D23: F | E23: 60 | F23: 0.26319444 | G23: 0.26388889 | H23: 77 | I23: 0.32083333 | J23: 0.32083333 | K23: 34 | L23: 0.37083333 | M23: 0.37361111 | N23: 37 | O23: 0.44722222 | P23: 0.44861111 | Q23: 37 | R23: 0.50833333 | S23: 0.51041667 | T23: 33 | U23: 0.56597222 | V23: 0.56666667 | W23: 30 | X23: 0.60555556 | Y23: 0.61041667 | Z23: 29 | AB23: 0.70347222 | AC23: 27 | AD23: 0.75694444 | AE23: 0.76111111 | AF23: 27 | AG23: 0.84236111 | AH23: 0.84791667 | AI23: 25 | AJ23: 0.90902778 | AK23: 0.9125 | AL23: 23 | AM23: 0.99791667 | AN23: 0.0013888889 | AO23: 20 | AP23: 0.056944444 | AQ23: 0.072222222 | AR23: 21 | AS23: 0.13541667 | AT23: 0.13958333 | AU23: 20 | AV23: 0.24027778 | AW23: 0.24791667 | AX23: 21 | AY23: 0.32222222 | AZ23: 0.32361111 | BA23: 22 | BB23: 44787.374
B24: KEITH NADEAU | C24: 650 | D24: M | E24: 28 | F24: 0.25972222 | G24: 0.26041667 | H24: 36 | I24: 0.31180556 | J24: 0.31180556 | K24: 31 | L24: 0.36875 | M24: 0.37013889 | N24: 24 | O24: 0.44027778 | P24: 0.44097222 | Q24: 24 | R24: 0.49861111 | S24: 0.5 | T24: 19 | U24: 0.55208333 | V24: 0.55347222 | W24: 18 | X24: 0.59097222 | Y24: 0.59375 | Z24: 15 | AB24: 0.68611111 | AC24: 17 | AD24: 0.74305556 | AE24: 0.74583333 | AF24: 22 | AG24: 0.83055556 | AH24: 0.84236111 | AI24: 22 | AJ24: 0.90486111 | AK24: 0.90763889 | AL24: 21 | AM24: 0.99652778 | AN24: 0.99861111 | AO24: 21 | AP24: 0.059722222 | AQ24: 0.065972222 | AR24: 22 | AS24: 0.13819444 | AT24: 0.14513889 | AU24: 25 | AV24: 0.26041667 | AW24: 0.2625 | AX24: 24 | AY24: 0.3375 | AZ24: 0.3375 | BA24: 23 | BB24: 44787.38
B25: NICHOLAS MITCHELL | C25: 644 | D25: M | E25: 13 | F25: 0.25416667 | G25: 0.25486111 | H25: 13 | I25: 0.30138889 | J25: 0.30138889 | K25: 16 | L25: 0.35902778 | M25: 0.3625 | N25: 23 | O25: 0.43680556 | P25: 0.43819444 | Q25: 22 | R25: 0.49722222 | S25: 0.5 | T25: 23 | U25: 0.55694444 | V25: 0.56041667 | W25: 25 | X25: 0.60069444 | Y25: 0.60833333 | Z25: 24 | AB25: 0.69861111 | AC25: 26 | AD25: 0.75208333 | AE25: 0.75416667 | AF25: 26 | AG25: 0.83125 | AH25: 0.84305556 | AI25: 24 | AJ25: 0.90763889 | AK25: 0.9125 | AL25: 24 | AM25: 0 | AN25: 0.0027777778 | AO25: 22 | AP25: 0.061805556 | AQ25: 0.069444444 | AR25: 20 | AS25: 0.13333333 | AT25: 0.13680556 | AU25: 22 | AV25: 0.25 | AW25: 0.25347222 | AX25: 23 | AY25: 0.33611111 | AZ25: 0.33819444 | BA25: 24 | BB25: 44787.396
B26: DAVID LARSON | C26: 611 | D26: M | E26: 49 | F26: 0.26111111 | G26: 0.26180556 | H26: 50 | I26: 0.31388889 | J26: 0.31388889 | K26: 44 | L26: 0.37361111 | M26: 0.37847222 | N26: 41 | O26: 0.45 | P26: 0.45277778 | Q26: 41 | R26: 0.5125 | S26: 0.51527778 | T26: 38 | U26: 0.57013889 | V26: 0.57083333 | W26: 32 | X26: 0.60694444 | Y26: 0.61736111 | Z26: 33 | AB26: 0.71388889 | AC26: 34 | AD26: 0.77013889 | AE26: 0.77291667 | AF26: 34 | AG26: 0.86111111 | AH26: 0.87569444 | AI26: 37 | AJ26: 0.94652778 | AK26: 0.95 | AL26: 37 | AM26: 0.047222222 | AN26: 0.052777778 | AO26: 31 | AP26: 0.10763889 | AQ26: 0.12361111 | AR26: 33 | AS26: 0.19513889 | AT26: 0.19930556 | AU26: 31 | AV26: 0.29513889 | AW26: 0.29930556 | AX26: 26 | AY26: 0.35555556 | AZ26: 0.35555556 | BA26: 25 | BB26: 44787.398
B27: JIANHUI SHEN | C27: 692 | D27: M | E27: 45 | F27: 0.26111111 | G27: 0.26180556 | H27: 48 | I27: 0.31388889 | J27: 0.31388889 | K27: 53 | L27: 0.37638889 | M27: 0.38055556 | N27: 56 | O27: 0.46180556 | P27: 0.46527778 | Q27: 62 | R27: 0.53333333 | S27: 0.53541667 | T27: 62 | U27: 0.6 | V27: 0.60347222 | W27: 61 | X27: 0.64513889 | Y27: 0.65416667 | Z27: 59 | AB27: 0.75694444 | AC27: 57 | AD27: 0.8125 | AE27: 0.81527778 | AF27: 48 | AG27: 0.89513889 | AH27: 0.90763889 | AI27: 42 | AJ27: 0.97152778 | AK27: 0.97777778 | AL27: 38 | AM27: 0.059027778 | AN27: 0.065277778 | AO27: 34 | AP27: 0.11527778 | AQ27: 0.11875 | AR27: 30 | AS27: 0.18888889 | AT27: 0.19444444 | AU27: 28 | AV27: 0.29166667 | AW27: 0.29444444 | AX27: 27 | AY27: 0.35625 | AZ27: 0.35625 | BA27: 26 | BB27: 44787.398
B28: DAVID PEPPELMAN | C28: 662 | D28: M | E28: 53 | F28: 0.26319444 | G28: 0.26388889 | H28: 187 | I28: 0.35277778 | J28: 0.35277778 | K28: 46 | L28: 0.375 | M28: 0.37847222 | N28: 43 | O28: 0.45277778 | P28: 0.45486111 | Q28: 43 | R28: 0.5125 | S28: 0.51527778 | T28: 41 | U28: 0.57083333 | V28: 0.57291667 | W28: 35 | X28: 0.61111111 | Y28: 0.61666667 | Z28: 31 | AB28: 0.71111111 | AC28: 30 | AD28: 0.76666667 | AE28: 0.76944444 | AF28: 29 | AG28: 0.84930556 | AH28: 0.85625 | AI28: 28 | AJ28: 0.92916667 | AK28: 0.93194444 | AL28: 26 | AM28: 0.021527778 | AN28: 0.025 | AO28: 24 | AP28: 0.078472222 | AQ28: 0.088194444 | AR28: 25 | AS28: 0.15416667 | AT28: 0.15694444 | AU28: 23 | AV28: 0.25972222 | AW28: 0.26041667 | AX28: 25 | AY28: 0.34513889 | AZ28: 0.34652778 | BA28: 27 | BB28: 44787.408
B29: BILL TRYON | C29: 715 | D29: M | K29: 48 | L29: 0.375 | M29: 0.37916667 | N29: 44 | O29: 0.45277778 | P29: 0.45486111 | Q29: 44 | R29: 0.5125 | S29: 0.51527778 | T29: 42 | U29: 0.57152778 | V29: 0.57291667 | W29: 39 | X29: 0.61180556 | Y29: 0.61944444 | Z29: 34 | AB29: 0.71388889 | AC29: 33 | AD29: 0.77013889 | AE29: 0.77291667 | AF29: 33 | AG29: 0.86041667 | AH29: 0.87222222 | AI29: 32 | AJ29: 0.93958333 | AK29: 0.94236111 | AL29: 32 | AM29: 0.035416667 | AN29: 0.038194444 | AO29: 29 | AP29: 0.099305556 | AQ29: 0.11597222 | AR29: 29 | AS29: 0.18680556 | AT29: 0.19166667 | AU29: 29 | AV29: 0.29305556 | AW29: 0.29722222 | AX29: 29 | AY29: 0.36527778 | AZ29: 0.36597222 | BA29: 28 | BB29: 44787.412
B30: PERRIN SMITH | C30: 697 | D30: M | E30: 34 | F30: 0.25972222 | G30: 0.26041667 | H30: 28 | I30: 0.30694444 | J30: 0.30694444 | K30: 21 | L30: 0.36319444 | M30: 0.36388889 | N30: 15 | O30: 0.42986111 | P30: 0.43263889 | Q30: 13 | R30: 0.48680556 | S30: 0.48888889 | T30: 14 | U30: 0.54444444 | V30: 0.54722222 | W30: 14 | X30: 0.5875 | Y30: 0.59513889 | Z30: 14 | AB30: 0.68541667 | AC30: 16 | AD30: 0.74305556 | AE30: 0.74583333 | AF30: 24 | AG30: 0.83055556 | AH30: 0.84097222 | AI30: 23 | AJ30: 0.90555556 | AK30: 0.90902778 | AL30: 22 | AM30: 0.99652778 | AN30: 0.0027777778 | AO30: 23 | AP30: 0.070138889 | AQ30: 0.075 | AR30: 23 | AS30: 0.14722222 | AT30: 0.15208333 | AU30: 26 | AV30: 0.26805556 | AW30: 0.27986111 | AX30: 28 | AY30: 0.36180556 | AZ30: 0.35694444 | BA30: 29 | BB30: 44787.417
B31: THOMAS CAMENISCH | C31: 527 | D31: M | E31: 23 | F31: 0.25763889 | G31: 0.25833333 | H31: 20 | I31: 0.30625 | J31: 0.30625 | K31: 18 | L31: 0.3625 | M31: 0.36388889 | N31: 18 | O31: 0.43472222 | P31: 0.43611111 | Q31: 19 | R31: 0.49444444 | S31: 0.49583333 | T31: 21 | U31: 0.55416667 | V31: 0.55763889 | W31: 22 | X31: 0.59930556 | Y31: 0.61111111 | Z31: 30 | AB31: 0.70416667 | AC31: 31 | AD31: 0.76805556 | AE31: 0.77152778 | AF31: 32 | AG31: 0.85972222 | AH31: 0.87708333 | AI31: 35 | AJ31: 0.94513889 | AK31: 0.94861111 | AL31: 35 | AM31: 0.041666667 | AN31: 0.046527778 | AO31: 33 | AP31: 0.11111111 | AQ31: 0.12152778 | AR31: 32 | AS31: 0.19513889 | AT31: 0.20069444 | AU31: 35 | AV31: 0.31180556 | AW31: 0.31527778 | AX31: 33 | AY31: 0.38263889 | AZ31: 0.38263889 | BA31: 30 | BB31: 44787.419
B32: JILL DENNES | C32: 550 | D32: F | E32: 76 | F32: 0.26597222 | G32: 0.26666667 | K32: 82 | L32: 0.38819444 | M32: 0.39652778 | N32: 81 | O32: 0.47847222 | P32: 0.48055556 | Q32: 76 | R32: 0.54513889 | S32: 0.55416667 | T32: 78 | U32: 0.61666667 | V32: 0.61944444 | W32: 70 | X32: 0.6625 | Y32: 0.67083333 | Z32: 65 | AB32: 0.77013889 | AC32: 62 | AD32: 0.82222222 | AE32: 0.82361111 | AF32: 56 | AG32: 0.91388889 | AH32: 0.925 | AI32: 51 | AJ32: 0.99791667 | AK32: 0.0034722222 | AL32: 53 | AM32: 0.10555556 | AN32: 0.10763889 | AO32: 42 | AP32: 0.15416667 | AQ32: 0.16041667 | AR32: 45 | AS32: 0.23958333 | AT32: 0.24583333 | AU32: 41 | AV32: 0.32777778 | AW32: 0.32777778 | AX32: 32 | AY32: 0.38263889 | AZ32: 0.38263889 | BA32: 31 | BB32: 44787.423
B33: RYAN WILLIAMS | C33: 729 | D33: M | E33: 67 | F33: 0.26388889 | G33: 0.26458333 | H33: 71 | I33: 0.32083333 | J33: 0.32083333 | K33: 63 | L33: 0.38402778 | M33: 0.38611111 | N33: 62 | O33: 0.46527778 | P33: 0.46666667 | Q33: 59 | R33: 0.52916667 | S33: 0.53055556 | T33: 53 | U33: 0.58819444 | V33: 0.58958333 | W33: 48 | X33: 0.62916667 | Y33: 0.63125 | Z33: 45 | AB33: 0.73194444 | AC33: 45 | AD33: 0.79027778 | AE33: 0.79236111 | AF33: 39 | AG33: 0.87708333 | AH33: 0.88333333 | AI33: 39 | AJ33: 0.95763889 | AK33: 0.96180556 | AL33: 39 | AM33: 0.0625 | AN33: 0.065972222 | AO33: 35 | AP33: 0.12152778 | AQ33: 0.12777778 | AR33: 34 | AS33: 0.19722222 | AT33: 0.20069444 | AU33: 30 | AV33: 0.29305556 | AW33: 0.29722222 | AX33: 31 | AY33: 0.37708333 | AZ33: 0.37986111 | BA33: 32 | BB33: 44787.429
B34: RUFUS CHAFFEE | C34: 530 | D34: M | E34: 46 | F34: 0.26111111 | G34: 0.26180556 | H34: 40 | I34: 0.31319444 | J34: 0.31319444 | K34: 57 | L34: 0.37847222 | M34: 0.38055556 | N34: 49 | O34: 0.45694444 | P34: 0.45902778 | Q34: 49 | R34: 0.52083333 | S34: 0.52291667 | T34: 51 | U34: 0.5875 | V34: 0.58888889 | W34: 49 | X34: 0.63055556 | Y34: 0.63402778 | Z34: 48 | AB34: 0.73888889 | AC34: 49 | AD34: 0.8 | AE34: 0.80208333 | AF34: 50 | AG34: 0.90138889 | AH34: 0.91805556 | AI34: 47 | AJ34: 0.99097222 | AK34: 0.99305556 | AL34: 41 | AM34: 0.074305556 | AN34: 0.075694444 | AO34: 38 | AP34: 0.13472222 | AQ34: 0.14305556 | AR34: 37 | AS34: 0.2125 | AT34: 0.21736111 | AU34: 34 | AV34: 0.31041667 | AW34: 0.31180556 | AX34: 34 | AY34: 0.38263889 | AZ34: 0.38333333 | BA34: 33 | BB34: 44787.431
B35: PHILIP SAMOTUS | C35: 686 | D35: M | E35: 43 | F35: 0.26041667 | G35: 0.26180556 | H35: 49 | I35: 0.31388889 | J35: 0.31388889 | K35: 55 | L35: 0.37708333 | M35: 0.37986111 | N35: 51 | O35: 0.45902778 | P35: 0.46041667 | Q35: 53 | R35: 0.52291667 | S35: 0.52569444 | T35: 55 | U35: 0.58888889 | V35: 0.59097222 | W35: 53 | X35: 0.63333333 | Y35: 0.63611111 | Z35: 44 | AB35: 0.72847222 | AC35: 42 | AD35: 0.78541667 | AE35: 0.7875 | AF35: 38 | AG35: 0.87152778 | AH35: 0.87569444 | AI35: 34 | AJ35: 0.94166667 | AK35: 0.94513889 | AL35: 28 | AM35: 0.03125 | AN35: 0.032638889 | AO35: 27 | AP35: 0.088888889 | AQ35: 0.092361111 | AR35: 27 | AS35: 0.16319444 | AT35: 0.16597222 | AU35: 27 | AV35: 0.27638889 | AW35: 0.27986111 | AX35: 30 | AY35: 0.36805556 | AZ35: 0.36180556 | BA35: 34 | BB35: 44787.438
B36: JOSHUA ROLLINS | C36: 684 | D36: M | E36: 121 | F36: 0.27013889 | G36: 0.27083333 | H36: 102 | I36: 0.32569444 | J36: 0.32569444 | K36: 66 | L36: 0.38541667 | M36: 0.3875 | N36: 53 | O36: 0.45972222 | P36: 0.46111111 | Q36: 47 | R36: 0.51805556 | S36: 0.52361111 | T36: 47 | U36: 0.58263889 | V36: 0.58541667 | W36: 46 | X36: 0.62361111 | Y36: 0.6375 | Z36: 42 | AB36: 0.72638889 | AC36: 36 | AD36: 0.77569444 | AE36: 0.78125 | AF36: 35 | AG36: 0.86458333 | AH36: 0.88333333 | AI36: 36 | AJ36: 0.94513889 | AK36: 0.94930556 | AL36: 31 | AM36: 0.034722222 | AN36: 0.038888889 | AO36: 28 | AP36: 0.097222222 | AQ36: 0.11805556 | AR36: 28 | AS36: 0.18055556 | AT36: 0.1875 | AU36: 32 | AV36: 0.29791667 | AW36: 0.30277778 | AX36: 35 | AY36: 0.38611111 | AZ36: 0.38611111 | BA36: 35 | BB36: 44787.44
B37: NORB BAIER | C37: 507 | D37: M | E37: 44 | F37: 0.26111111 | G37: 0.26180556 | H37: 32 | I37: 0.30763889 | J37: 0.30763889 | K37: 41 | L37: 0.37152778 | M37: 0.37847222 | N37: 52 | O37: 0.45972222 | P37: 0.46111111 | Q37: 50 | R37: 0.52152778 | S37: 0.525 | T37: 49 | U37: 0.58541667 | V37: 0.58819444 | W37: 47 | X37: 0.62777778 | Y37: 0.63263889 | Z37: 46 | AB37: 0.73333333 | AC37: 46 | AD37: 0.79375 | AE37: 0.8 | AF37: 45 | AG37: 0.88958333 | AH37: 0.90069444 | AI37: 41 | AJ37: 0.97083333 | AK37: 0.97777778 | AL37: 40 | AM37: 0.072916667 | AN37: 0.080555556 | AO37: 36 | AP37: 0.12986111 | AQ37: 0.14305556 | AR37: 36 | AS37: 0.21180556 | AT37: 0.21527778 | AU37: 36 | AV37: 0.31388889 | AW37: 0.31944444 | AX37: 36 | AY37: 0.39444444 | AZ37: 0.39652778 | BA37: 36 | BB37: 44787.441
B38: BOB BAUER | C38: 511 | D38: M | E38: 37 | F38: 0.26041667 | G38: 0.26180556 | H38: 22 | I38: 0.30625 | J38: 0.30625 | K38: 27 | L38: 0.36597222 | M38: 0.37013889 | N38: 36 | O38: 0.44652778 | P38: 0.44791667 | Q38: 45 | R38: 0.51319444 | S38: 0.51527778 | T38: 46 | U38: 0.57986111 | V38: 0.58125 | W38: 45 | X38: 0.62222222 | Y38: 0.63194444 | Z38: 50 | AB38: 0.74375 | AC38: 50 | AD38: 0.80277778 | AE38: 0.80763889 | AF38: 46 | AG38: 0.89166667 | AH38: 0.91111111 | AI38: 43 | AJ38: 0.98055556 | AK38: 0.98680556 | AL38: 42 | AM38: 0.076388889 | AN38: 0.080555556 | AO38: 37 | AP38: 0.13333333 | AQ38: 0.15138889 | AR38: 38 | AS38: 0.21458333 | AT38: 0.22152778 | AU38: 37 | AV38: 0.31666667 | AW38: 0.32638889 | AX38: 38 | AY38: 0.39791667 | AZ38: 0.39930556 | BA38: 37 | BB38: 44787.442
B39: ROBERT MITCHELL | C39: 645 | D39: M | E39: 56 | F39: 0.26319444 | G39: 0.26388889 | H39: 72 | I39: 0.32083333 | J39: 0.32083333 | K39: 72 | L39: 0.38680556 | M39: 0.38958333 | N39: 61 | O39: 0.46458333 | P39: 0.46597222 | Q39: 54 | R39: 0.525 | S39: 0.52777778 | T39: 50 | U39: 0.5875 | V39: 0.59027778 | W39: 52 | X39: 0.63125 | Y39: 0.64166667 | Z39: 47 | AB39: 0.73402778 | AC39: 44 | AD39: 0.79027778 | AE39: 0.79375 | AF39: 40 | AG39: 0.87708333 | AH39: 0.88958333 | AI39: 38 | AJ39: 0.94930556 | AK39: 0.95694444 | AL39: 36 | AM39: 0.045138889 | AN39: 0.050694444 | AO39: 32 | AP39: 0.10902778 | AQ39: 0.13333333 | AR39: 35 | AS39: 0.2 | AT39: 0.20763889 | AU39: 33 | AV39: 0.30763889 | AW39: 0.32222222 | AX39: 37 | AY39: 0.39583333 | AZ39: 0.39791667 | BA39: 38 | BB39: 44787.444
B40: DEREK BREITENSTINE | C40: 523 | D40: M | E40: 114 | F40: 0.26944444 | G40: 0.27013889 | H40: 100 | I40: 0.32569444 | J40: 0.32569444 | K40: 81 | L40: 0.38819444 | M40: 0.39375 | N40: 70 | O40: 0.47222222 | P40: 0.47361111 | Q40: 61 | R40: 0.51875 | S40: 0.53680556 | T40: 58 | U40: 0.59583333 | V40: 0.6 | W40: 55 | X40: 0.64097222 | Y40: 0.65555556 | Z40: 57 | AB40: 0.75625 | AC40: 55 | AD40: 0.8125 | AE40: 0.82083333 | AF40: 51 | AG40: 0.90763889 | AH40: 0.91875 | AI40: 49 | AJ40: 0.99305556 | AK40: 0.99930556 | AL40: 48 | AM40: 0.097916667 | AN40: 0.10694444 | AO40: 43 | AP40: 0.15416667 | AQ40: 0.16736111 | AR40: 41 | AS40: 0.22986111 | AT40: 0.23680556 | AU40: 40 | AV40: 0.32777778 | AW40: 0.33541667 | AX40: 39 | AY40: 0.40277778 | AZ40: 0.40347222 | BA40: 39 | BB40: 44787.447
...

Sheet splits v2
B1: Bib Number | C1: AS1 arr order | D1: AS1 arr TOD | E1: AS1 dep TOD | F1: AS2 arr order | G1: AS2 arr TOD | H1: AS2dep TOD | I1: AS3 arr order | J1: AS3 arr TOD | K1: AS3 dep TOD | L1: AS4 arr order | M1: AS4 arr TOD | N1: AS4 dep TOD | O1: AS5 arr order | P1: AS5 arr TOD | Q1: AS5 dep TOD | R1: AS6 arr order | S1: AS6 arr TOD | T1: AS6 dep TOD | U1: AS7 arr order | V1: AS7 arr TOD | W1: AS7 dep TOD | X1: AS8 arr order | Y1: AS8 arr TOD | Z1: AS8 dep TOD | AA1: AS9 arr order | AB1: AS9 arr TOD | AC1: AS9 dep TOD | AD1: AS10 arr order | AE1: AS10 arr TOD | AF1: AS10 dep TOD | AG1: AS11 arr order | AH1: AS11 arr TOD | AI1: AS11 dep TOD | AJ1: AS12 arr order | AK1: AS12 arr TOD | AL1: AS12 dep TOD | AM1: AS13 arr order | AN1: AS13 arr TOD | AO1: AS13 dep TOD | AP1: AS14 arr order | AQ1: AS14 arr TOD | AR1: AS14 dep TOD | AS1: AS15 arr order | AT1: AS15 arr TOD | AU1: AS15 dep TOD | AV1: AS16 arr order | AW1: AS16 arr TOD | AX1: AS16 dep TOD | AY1: F arr order | AZ1: F arr TOD
B2: 537 | C2: 1 | D2: 0.25138889 | E2: 0.25208333 | F2: 9 | G2: 0.29444444 | H2: 0.29444444 | I2: 3 | J2: 0.34097222 | K2: 0.34236111 | L2: 1 | M2: 0.39513889 | N2: 0.39583333 | O2: 1 | P2: 0.43680556 | Q2: 0.43680556 | R2: 1 | S2: 0.47708333 | T2: 0.47847222 | U2: 1 | V2: 0.50972222 | W2: 0.51111111 | X2: 1 | Z2: 0.57430556 | AA2: 1 | AB2: 0.61527778 | AC2: 0.61666667 | AD2: 1 | AE2: 0.67916667 | AF2: 0.68333333 | AG2: 1 | AH2: 0.72777778 | AI2: 0.72847222 | AJ2: 1 | AK2: 0.78680556 | AL2: 0.78958333 | AM2: 1 | AN2: 0.82291667 | AO2: 0.82708333 | AP2: 1 | AQ2: 0.87361111 | AR2: 0.875 | AS2: 1 | AT2: 0.94583333 | AU2: 0.95 | AV2: 1 | AW2: 0.0048611111 | AX2: 0.0076388889
B3: 596 | C3: 3 | D3: 0.25138889 | E3: 0.25208333 | F3: 1 | G3: 0.29097222 | H3: 0.29166667 | I3: 2 | J3: 0.34097222 | K3: 0.34305556 | L3: 2 | M3: 0.40069444 | N3: 0.40138889 | O3: 2 | P3: 0.44722222 | Q3: 0.44930556 | R3: 2 | S3: 0.50763889 | T3: 0.50902778 | U3: 2 | V3: 0.54097222 | W3: 0.54305556 | X3: 2 | Z3: 0.62291667 | AA3: 2 | AB3: 0.66736111 | AC3: 0.67013889 | AD3: 2 | AE3: 0.73958333 | AF3: 0.74583333 | AG3: 2 | AH3: 0.8 | AI3: 0.80138889 | AJ3: 2 | AK3: 0.87152778 | AL3: 0.87361111 | AM3: 2 | AN3: 0.91527778 | AO3: 0.92013889 | AP3: 2 | AQ3: 0.97430556 | AR3: 0.97777778 | AS3: 2 | AT3: 0.056944444 | AU3: 0.060416667 | AV3: 2 | AW3: 0.11875 | AX3: 0.11944444
B4: 513 | C4: 9 | D4: 0.25208333 | E4: 0.25277778 | F4: 7 | G4: 0.29236111 | H4: 0.29236111 | I4: 9 | J4: 0.34583333 | K4: 0.34791667 | L4: 8 | M4: 0.41666667 | N4: 0.41875 | O4: 8 | P4: 0.47291667 | Q4: 0.47430556 | R4: 10 | S4: 0.53055556 | T4: 0.53263889 | U4: 12 | V4: 0.57430556 | W4: 0.57777778 | X4: 9 | Z4: 0.65902778 | AA4: 8 | AB4: 0.70625 | AC4: 0.70972222 | AD4: 8 | AE4: 0.78333333 | AF4: 0.78680556 | AG4: 7 | AH4: 0.84097222 | AI4: 0.84375 | AJ4: 5 | AK4: 0.91180556 | AL4: 0.91736111 | AM4: 6 | AN4: 0.96319444 | AO4: 0.96666667 | AP4: 4 | AQ4: 0.020138889 | AR4: 0.023611111 | AS4: 4 | AT4: 0.10625 | AU4: 0.11041667 | AV4: 3 | AW4: 0.16388889 | AX4: 0.16458333
B5: 620 | C5: 10 | D5: 0.25208333 | E5: 0.25277778 | F5: 8 | G5: 0.29236111 | H5: 0.29236111 | I5: 6 | J5: 0.34444444 | K5: 0.34652778 | L5: 7 | M5: 0.41597222 | N5: 0.41666667 | O5: 7 | P5: 0.47083333 | Q5: 0.47222222 | R5: 7 | S5: 0.51944444 | T5: 0.52083333 | U5: 7 | V5: 0.55277778 | W5: 0.55763889 | X5: 6 | Z5: 0.64305556 | AA5: 5 | AB5: 0.69166667 | AC5: 0.69375 | AD5: 5 | AE5: 0.76736111 | AF5: 0.77013889 | AG5: 4 | AH5: 0.82569444 | AI5: 0.82708333 | AJ5: 4 | AK5: 0.90277778 | AL5: 0.90486111 | AM5: 3 | AN5: 0.94652778 | AO5: 0.95069444 | AP5: 3 | AQ5: 0.0076388889 | AR5: 0.011111111 | AS5: 3 | AT5: 0.10277778 | AU5: 0.10555556 | AV5: 4 | AW5: 0.17291667 | AX5: 0.17361111
B6: 689 | C6: 12 | D6: 0.25416667 | E6: 0.25416667 | I6: 13 | J6: 0.35555556 | K6: 0.35902778 | L6: 14 | M6: 0.42847222 | N6: 0.42916667 | O6: 14 | P6: 0.48958333 | Q6: 0.49097222 | R6: 13 | S6: 0.54375 | T6: 0.54444444 | U6: 13 | V6: 0.57916667 | W6: 0.58680556 | X6: 10 | Z6: 0.67013889 | AA6: 10 | AB6: 0.71736111 | AC6: 0.71944444 | AD6: 9 | AE6: 0.79166667 | AF6: 0.79930556 | AG6: 9 | AH6: 0.85416667 | AI6: 0.85763889 | AJ6: 6 | AK6: 0.92291667 | AL6: 0.925 | AM6: 5 | AN6: 0.9625 | AO6: 0.96805556 | AP6: 5 | AQ6: 0.022222222 | AR6: 0.025694444 | AS6: 5 | AT6: 0.10694444 | AU6: 0.1125 | AV6: 5 | AW6: 0.17638889 | AX6: 0.17708333
B7: 603 | C7: 6 | D7: 0.25208333 | E7: 0.25277778 | F7: 6 | G7: 0.29236111 | H7: 0.29236111 | I7: 8 | J7: 0.34583333 | K7: 0.34791667 | L7: 9 | M7: 0.41666667 | N7: 0.41875 | O7: 9 | P7: 0.47291667 | Q7: 0.475 | R7: 8 | S7: 0.52291667 | T7: 0.525 | U7: 8 | V7: 0.55902778 | W7: 0.56319444 | X7: 7 | Z7: 0.64652778 | AA7: 7 | AB7: 0.70069444 | AC7: 0.70694444 | AD7: 7 | AE7: 0.78333333 | AF7: 0.79305556 | AG7: 8 | AH7: 0.84861111 | AI7: 0.85347222 | AJ7: 7 | AK7: 0.92430556 | AL7: 0.92708333 | AM7: 7 | AN7: 0.97222222 | AO7: 0.97708333 | AP7: 6 | AQ7: 0.034722222 | AR7: 0.038888889 | AS7: 6 | AT7: 0.12361111 | AU7: 0.12638889 | AV7: 6 | AW7: 0.17777778 | AX7: 0.17777778
B8: 543 | C8: 26 | D8: 0.25972222 | E8: 0.26041667 | I8: 24 | J8: 0.36388889 | K8: 0.36736111 | L8: 19 | M8: 0.43541667 | N8: 0.4375 | O8: 16 | P8: 0.49236111 | Q8: 0.49513889 | R8: 16 | S8: 0.54861111 | T8: 0.55138889 | U8: 16 | V8: 0.59097222 | W8: 0.60208333 | X8: 17 | Z8: 0.69097222 | AA8: 14 | AB8: 0.74027778 | AC8: 0.74305556 | AD8: 12 | AE8: 0.81597222 | AF8: 0.82430556 | AG8: 12 | AH8: 0.875 | AI8: 0.88055556 | AJ8: 10 | AK8: 0.94652778 | AL8: 0.95208333 | AM8: 9 | AN8: 0.99097222 | AO8: 0.99583333 | AP8: 8 | AQ8: 0.049305556 | AR8: 0.052083333 | AS8: 7 | AT8: 0.13888889 | AU8: 0.14236111 | AV8: 7 | AW8: 0.25833333 | AX8: 0.21875
B9: 515 | C9: 16 | D9: 0.25694444 | E9: 0.25694444 | F9: 16 | G9: 0.30208333 | H9: 0.30208333 | I9: 14 | J9: 0.35902778 | K9: 0.35972222 | L9: 13 | M9: 0.42777778 | N9: 0.42847222 | O9: 12 | P9: 0.48263889 | Q9: 0.48333333 | R9: 12 | S9: 0.53402778 | T9: 0.53472222 | U9: 9 | V9: 0.57013889 | W9: 0.57152778 | X9: 8 | Z9: 0.65902778 | AA9: 9 | AB9: 0.71319444 | AC9: 0.71458333 | AD9: 10 | AE9: 0.79305556 | AF9: 0.79444444 | AG9: 10 | AH9: 0.85555556 | AI9: 0.85763889 | AJ9: 9 | AK9: 0.93819444 | AL9: 0.94027778 | AM9: 10 | AN9: 0.99236111 | AO9: 0.99444444 | AP9: 10 | AQ9: 0.056944444 | AR9: 0.059027778 | AS9: 9 | AT9: 0.15416667 | AU9: 0.15625 | AV9: 8 | AW9: 0.225 | AX9: 0.22638889
B10: 563 | C10: 7 | D10: 0.25208333 | E10: 0.25277778 | I10: 7 | J10: 0.34583333 | K10: 0.34791667 | L10: 6 | M10: 0.41597222 | N10: 0.41666667 | O10: 6 | P10: 0.47083333 | Q10: 0.47222222 | R10: 5 | S10: 0.51805556 | T10: 0.51944444 | U10: 6 | V10: 0.55277778 | W10: 0.55555556 | X10: 5 | Z10: 0.64166667 | AA10: 6 | AB10: 0.69166667 | AC10: 0.69375 | AD10: 6 | AE10: 0.77152778 | AF10: 0.775 | AG10: 6 | AH10: 0.83958333 | AI10: 0.84166667 | AJ10: 8 | AK10: 0.92986111 | AL10: 0.93263889 | AM10: 8 | AN10: 0.98680556 | AO10: 0.98958333 | AP10: 9 | AQ10: 0.050694444 | AR10: 0.052083333 | AS10: 8 | AT10: 0.15277778 | AU10: 0.15694444 | AV10: 9 | AW10: 0.2375 | AX10: 0.23819444
B11: 685 | C11: 31 | D11: 0.25972222 | E11: 0.26041667 | F11: 33 | G11: 0.30902778 | H11: 0.30902778 | I11: 33 | J11: 0.36875 | K11: 0.37083333 | L11: 29 | M11: 0.44513889 | N11: 0.44583333 | O11: 26 | P11: 0.50208333 | Q11: 0.50416667 | R11: 28 | S11: 0.56180556 | T11: 0.56319444 | U11: 28 | V11: 0.60277778 | W11: 0.60625 | X11: 22 | Z11: 0.69652778 | AA11: 21 | AB11: 0.74861111 | AC11: 0.75347222 | AD11: 19 | AE11: 0.82916667 | AF11: 0.83541667 | AG11: 17 | AH11: 0.89583333 | AI11: 0.89930556 | AJ11: 14 | AK11: 0.96736111 | AL11: 0.97152778 | AM11: 11 | AN11: 0.0125 | AO11: 0.015277778 | AP11: 11 | AQ11: 0.072222222 | AR11: 0.076388889 | AS11: 10 | AT11: 0.16597222 | AU11: 0.16944444 | AV11: 10 | AW11: 0.24097222 | AX11: 0.24236111
B12: 731 | C12: 24 | D12: 0.25902778 | E12: 0.25972222 | F12: 136 | G12: 0.33402778 | H12: 0.33402778 | I12: 30 | J12: 0.36736111 | K12: 0.36875 | L12: 25 | M12: 0.44166667 | N12: 0.44236111 | O12: 25 | P12: 0.5 | Q12: 0.50138889 | R12: 22 | S12: 0.55555556 | T12: 0.55625 | U12: 20 | V12: 0.59305556 | W12: 0.59444444 | X12: 13 | Z12: 0.68541667 | AA12: 12 | AB12: 0.73680556 | AC12: 0.7375 | AD12: 13 | AE12: 0.81666667 | AF12: 0.81875 | AG12: 13 | AH12: 0.875 | AI12: 0.87708333 | AJ12: 12 | AK12: 0.96180556 | AL12: 0.96388889 | AM12: 12 | AN12: 0.013888889 | AO12: 0.015972222 | AP12: 12 | AQ12: 0.08125 | AR12: 0.083333333 | AS12: 12 | AT12: 0.17986111 | AU12: 0.18263889 | AV12: 11 | AW12: 0.25138889 | AX12: 0.25138889
B13: 601 | C13: 11 | D13: 0.25416667 | E13: 0.25416667 | F13: 12 | G13: 0.29861111 | H13: 0.29861111 | I13: 15 | J13: 0.35902778 | K13: 0.36180556 | L13: 22 | M13: 0.43680556 | N13: 0.43819444 | O13: 20 | P13: 0.49583333 | Q13: 0.49791667 | R13: 20 | S13: 0.55347222 | T13: 0.55555556 | U13: 19 | V13: 0.59305556 | W13: 0.59791667 | X13: 19 | Z13: 0.69236111 | AA13: 19 | AB13: 0.74513889 | AC13: 0.74722222 | AD13: 16 | AE13: 0.82291667 | AF13: 0.82777778 | AG13: 15 | AH13: 0.88819444 | AI13: 0.88958333 | AJ13: 16 | AK13: 0.96944444 | AL13: 0.97222222 | AM13: 13 | AN13: 0.021527778 | AO13: 0.027083333 | AP13: 13 | AQ13: 0.089583333 | AR13: 0.093055556 | AS13: 13 | AT13: 0.18402778 | AU13: 0.18888889 | AV13: 12 | AW13: 0.25138889 | AX13: 0.25138889
B14: 602 | C14: 101 | D14: 0.26875 | E14: 0.26944444 | F14: 82 | G14: 0.32152778 | H14: 0.32152778 | I14: 60 | J14: 0.38194444 | K14: 0.38472222 | L14: 47 | M14: 0.45555556 | N14: 0.45694444 | O14: 40 | P14: 0.5125 | Q14: 0.51458333 | R14: 35 | S14: 0.56666667 | T14: 0.57013889 | U14: 34 | V14: 0.60972222 | W14: 0.61319444 | X14: 25 | Z14: 0.69930556 | AA14: 24 | AB14: 0.74930556 | AC14: 0.75208333 | AD14: 23 | AE14: 0.83055556 | AF14: 0.84236111 | AG14: 20 | AH14: 0.90138889 | AI14: 0.90416667 | AJ14: 18 | AK14: 0.97916667 | AL14: 0.98194444 | AM14: 17 | AN14: 0.03125 | AO14: 0.034722222 | AP14: 15 | AQ14: 0.096527778 | AR14: 0.10069444 | AS14: 14 | AT14: 0.19375 | AU14: 0.19583333 | AV14: 13 | AW14: 0.26111111 | AX14: 0.25763889
B15: 618 | C15: 8 | D15: 0.25208333 | E15: 0.25277778 | F15: 5 | G15: 0.29236111 | H15: 0.29305556 | I15: 4 | J15: 0.34375 | K15: 0.34513889 | L15: 4 | M15: 0.41111111 | N15: 0.41319444 | O15: 4 | P15: 0.46319444 | Q15: 0.46527778 | R15: 3 | S15: 0.51180556 | T15: 0.51319444 | U15: 3 | V15: 0.55 | W15: 0.55208333 | X15: 3 | Z15: 0.63055556 | AA15: 3 | AB15: 0.675 | AC15: 0.67847222 | AD15: 3 | AE15: 0.75486111 | AF15: 0.76319444 | AG15: 3 | AH15: 0.82083333 | AI15: 0.82430556 | AJ15: 3 | AK15: 0.90069444 | AL15: 0.90694444 | AM15: 4 | AN15: 0.95833333 | AO15: 0.96527778 | AP15: 7 | AQ15: 0.0375 | AR15: 0.05 | AS15: 11 | AT15: 0.17430556 | AU15: 0.17708333 | AV15: 14 | AW15: 0.26180556 | AX15: 0.26527778
B16: 561 | C16: 36 | D16: 0.26041667 | E16: 0.26180556 | I16: 38 | J16: 0.37152778 | K16: 0.37708333 | L16: 32 | M16: 0.44583333 | N16: 0.44722222 | O16: 31 | P16: 0.50347222 | Q16: 0.50486111 | R16: 29 | S16: 0.56388889 | T16: 0.56597222 | U16: 31 | V16: 0.60625 | W16: 0.61041667 | X16: 21 | Z16: 0.69583333 | AA16: 23 | AB16: 0.74930556 | AC16: 0.75208333 | AD16: 18 | AE16: 0.82916667 | AF16: 0.83888889 | AG16: 19 | AH16: 0.89861111 | AI16: 0.90069444 | AJ16: 17 | AK16: 0.97708333 | AL16: 0.98055556 | AM16: 15 | AN16: 0.027777778 | AO16: 0.031944444 | AP16: 16 | AQ16: 0.097916667 | AR16: 0.10625 | AS16: 15 | AT16: 0.19444444 | AU16: 0.19583333 | AV16: 15 | AW16: 0.26527778 | AX16: 0.26666667
B17: 529 | C17: 71 | D17: 0.26388889 | E17: 0.26458333 | F17: 65 | G17: 0.31875 | H17: 0.31875 | I17: 58 | J17: 0.37916667 | K17: 0.38125 | L17: 39 | M17: 0.45 | N17: 0.45069444 | O17: 38 | P17: 0.50972222 | Q17: 0.51111111 | R17: 31 | S17: 0.56527778 | T17: 0.56666667 | U17: 29 | V17: 0.60277778 | W17: 0.60625 | X17: 20 | Z17: 0.69513889 | AA17: 18 | AB17: 0.74444444 | AC17: 0.74583333 | AD17: 15 | AE17: 0.82291667 | AF17: 0.82638889 | AG17: 14 | AH17: 0.88541667 | AI17: 0.88680556 | AJ17: 15 | AK17: 0.96875 | AL17: 0.97222222 | AM17: 14 | AN17: 0.024305556 | AO17: 0.027083333 | AP17: 14 | AQ17: 0.095138889 | AR17: 0.097916667 | AS17: 16 | AT17: 0.19930556 | AU17: 0.20138889 | AV17: 16 | AW17: 0.27777778 | AX17: 0.27847222
B18: 629 | C18: 29 | D18: 0.25972222 | E18: 0.26041667 | F18: 27 | G18: 0.30694444 | H18: 0.30694444 | I18: 19 | J18: 0.3625 | K18: 0.36527778 | L18: 17 | M18: 0.43472222 | N18: 0.43680556 | O18: 17 | P18: 0.49305556 | Q18: 0.49652778 | R18: 18 | S18: 0.55069444 | T18: 0.55416667 | U18: 15 | V18: 0.59027778 | W18: 0.59583333 | X18: 18 | Z18: 0.69166667 | AA18: 20 | AB18: 0.74652778 | AC18: 0.75069444 | AD18: 17 | AE18: 0.82708333 | AF18: 0.83888889 | AG18: 18 | AH18: 0.89861111 | AJ18: 19 | AK18: 0.98263889 | AL18: 0.98819444 | AM18: 18 | AN18: 0.0375 | AO18: 0.047222222 | AP18: 17 | AQ18: 0.10833333 | AR18: 0.11458333 | AS18: 17 | AT18: 0.20972222 | AU18: 0.21736111 | AV18: 17 | AW18: 0.28611111 | AX18: 0.28611111
B19: 655 | C19: 54 | D19: 0.26319444 | E19: 0.26388889 | F19: 43 | G19: 0.31388889 | H19: 0.31388889 | I19: 40 | J19: 0.37152778 | K19: 0.37569444 | L19: 31 | M19: 0.44583333 | N19: 0.44722222 | O19: 27 | P19: 0.50208333 | Q19: 0.50416667 | R19: 27 | S19: 0.56041667 | T19: 0.5625 | U19: 26 | V19: 0.60208333 | W19: 0.60972222 | X19: 26 | Z19: 0.69930556 | AA19: 22 | AB19: 0.74861111 | AC19: 0.75347222 | AD19: 21 | AE19: 0.83055556 | AF19: 0.84375 | AG19: 21 | AH19: 0.90208333 | AI19: 0.90486111 | AJ19: 20 | AK19: 0.99027778 | AL19: 0.99305556 | AM19: 19 | AN19: 0.049305556 | AO19: 0.059722222 | AP19: 19 | AQ19: 0.12361111 | AR19: 0.12777778 | AS19: 19 | AT19: 0.23194444 | AU19: 0.23819444 | AV19: 18 | AW19: 0.30625 | AX19: 0.30625
B20: 567 | C20: 4 | D20: 0.25138889 | E20: 0.25208333 | I20: 5 | J20: 0.34375 | K20: 0.34513889 | L20: 12 | M20: 0.42430556 | N20: 0.42569444 | O20: 18 | P20: 0.49444444 | Q20: 0.49722222 | R20: 17 | S20: 0.55 | T20: 0.55208333 | U20: 21 | V20: 0.59652778 | W20: 0.60277778 | X20: 36 | Z20: 0.71597222 | AA20: 38 | AB20: 0.78125 | AC20: 0.78333333 | AD20: 41 | AE20: 0.87777778 | AF20: 0.88125 | AG20: 33 | AH20: 0.94097222 | AI20: 0.94305556 | AJ20: 29 | AK20: 0.03125 | AL20: 0.034722222 | AM20: 25 | AN20: 0.086111111 | AO20: 0.090972222 | AP20: 24 | AQ20: 0.15138889 | AR20: 0.15416667 | AS20: 21 | AT20: 0.24444444 | AU20: 0.24722222 | AV20: 19 | AW20: 0.31319444 | AX20: 0.31388889
B21: 702 | C21: 27 | D21: 0.25972222 | E21: 0.26041667 | F21: 23 | G21: 0.30625 | H21: 0.30625 | I21: 23 | J21: 0.36388889 | K21: 0.36736111 | L21: 20 | M21: 0.43541667 | N21: 0.4375 | O21: 15 | P21: 0.49166667 | Q21: 0.49513889 | R21: 15 | S21: 0.54861111 | T21: 0.55138889 | U21: 17 | V21: 0.59097222 | W21: 0.60277778 | X21: 16 | Z21: 0.69027778 | AA21: 15 | AB21: 0.74027778 | AC21: 0.74305556 | AD21: 11 | AE21: 0.81527778 | AF21: 0.81875 | AG21: 11 | AH21: 0.875 | AI21: 0.875 | AJ21: 11 | AK21: 0.96180556 | AL21: 0.96527778 | AM21: 16 | AN21: 0.029166667 | AO21: 0.049305556 | AP21: 18 | AQ21: 0.12083333 | AR21: 0.12430556 | AS21: 18 | AT21: 0.23125 | AU21: 0.23611111 | AV21: 20 | AW21: 0.31944444 | AX21: 0.31944444
B22: 728 | C22: 60 | D22: 0.26319444 | E22: 0.26388889 | F22: 77 | G22: 0.32083333 | H22: 0.32083333 | I22: 34 | J22: 0.37083333 | K22: 0.37361111 | L22: 37 | M22: 0.44722222 | N22: 0.44861111 | O22: 37 | P22: 0.50833333 | Q22: 0.51041667 | R22: 33 | S22: 0.56597222 | T22: 0.56666667 | U22: 30 | V22: 0.60555556 | W22: 0.61041667 | X22: 29 | Z22: 0.70347222 | AA22: 27 | AB22: 0.75694444 | AC22: 0.76111111 | AD22: 27 | AE22: 0.84236111 | AF22: 0.84791667 | AG22: 25 | AH22: 0.90902778 | AI22: 0.9125 | AJ22: 23 | AK22: 0.99791667 | AL22: 0.0013888889 | AM22: 20 | AN22: 0.056944444 | AO22: 0.072222222 | AP22: 21 | AQ22: 0.13541667 | AR22: 0.13958333 | AS22: 20 | AT22: 0.24027778 | AU22: 0.24791667 | AV22: 21 | AW22: 0.32222222 | AX22: 0.32361111
B23: 591 | C23: 169 | D23: 0.27430556 | E23: 0.275 | F23: 143 | G23: 0.33680556 | H23: 0.33680556 | I23: 110 | J23: 0.4 | K23: 0.40972222 | L23: 94 | M23: 0.48472222 | N23: 0.48611111 | O23: 79 | P23: 0.54722222 | Q23: 0.55 | R23: 67 | S23: 0.60694444 | T23: 0.60833333 | U23: 63 | V23: 0.64722222 | W23: 0.65486111 | X23: 52 | Z23: 0.74513889 | AA23: 48 | AB23: 0.79583333 | AC23: 0.79791667 | AD23: 37 | AE23: 0.87152778 | AF23: 0.87708333 | AG23: 31 | AH23: 0.93958333 | AI23: 0.94236111 | AJ23: 30 | AK23: 0.034722222 | AL23: 0.038194444 | AM23: 26 | AN23: 0.086111111 | AO23: 0.093055556 | AP23: 26 | AQ23: 0.15902778 | AR23: 0.16666667 | AS23: 24 | AT23: 0.25972222 | AU23: 0.26458333 | AV23: 22 | AW23: 0.32708333 | AX23: 0.32777778
B24: 644 | C24: 13 | D24: 0.25416667 | E24: 0.25486111 | F24: 13 | G24: 0.30138889 | H24: 0.30138889 | I24: 16 | J24: 0.35902778 | K24: 0.3625 | L24: 23 | M24: 0.43680556 | N24: 0.43819444 | O24: 22 | P24: 0.49722222 | Q24: 0.5 | R24: 23 | S24: 0.55694444 | T24: 0.56041667 | U24: 25 | V24: 0.60069444 | W24: 0.60833333 | X24: 24 | Z24: 0.69861111 | AA24: 26 | AB24: 0.75208333 | AC24: 0.75416667 | AD24: 26 | AE24: 0.83125 | AF24: 0.84305556 | AG24: 24 | AH24: 0.90763889 | AI24: 0.9125 | AJ24: 24 | AK24: 0 | AL24: 0.0027777778 | AM24: 22 | AN24: 0.061805556 | AO24: 0.069444444 | AP24: 20 | AQ24: 0.13333333 | AR24: 0.13680556 | AS24: 22 | AT24: 0.25 | AU24: 0.25347222 | AV24: 23 | AW24: 0.33611111 | AX24: 0.33819444
B25: 650 | C25: 28 | D25: 0.25972222 | E25: 0.26041667 | F25: 36 | G25: 0.31180556 | H25: 0.31180556 | I25: 31 | J25: 0.36875 | K25: 0.37013889 | L25: 24 | M25: 0.44027778 | N25: 0.44097222 | O25: 24 | P25: 0.49861111 | Q25: 0.5 | R25: 19 | S25: 0.55208333 | T25: 0.55347222 | U25: 18 | V25: 0.59097222 | W25: 0.59375 | X25: 15 | Z25: 0.68611111 | AA25: 17 | AB25: 0.74305556 | AC25: 0.74583333 | AD25: 22 | AE25: 0.83055556 | AF25: 0.84236111 | AG25: 22 | AH25: 0.90486111 | AI25: 0.90763889 | AJ25: 21 | AK25: 0.99652778 | AL25: 0.99861111 | AM25: 21 | AN25: 0.059722222 | AO25: 0.065972222 | AP25: 22 | AQ25: 0.13819444 | AR25: 0.14513889 | AS25: 25 | AT25: 0.26041667 | AU25: 0.2625 | AV25: 24 | AW25: 0.3375 | AX25: 0.3375
B26: 662 | C26: 53 | D26: 0.26319444 | E26: 0.26388889 | F26: 187 | G26: 0.35277778 | H26: 0.35277778 | I26: 46 | J26: 0.375 | K26: 0.37847222 | L26: 43 | M26: 0.45277778 | N26: 0.45486111 | O26: 43 | P26: 0.5125 | Q26: 0.51527778 | R26: 41 | S26: 0.57083333 | T26: 0.57291667 | U26: 35 | V26: 0.61111111 | W26: 0.61666667 | X26: 31 | Z26: 0.71111111 | AA26: 30 | AB26: 0.76666667 | AC26: 0.76944444 | AD26: 29 | AE26: 0.84930556 | AF26: 0.85625 | AG26: 28 | AH26: 0.92916667 | AI26: 0.93194444 | AJ26: 26 | AK26: 0.021527778 | AL26: 0.025 | AM26: 24 | AN26: 0.078472222 | AO26: 0.088194444 | AP26: 25 | AQ26: 0.15416667 | AR26: 0.15694444 | AS26: 23 | AT26: 0.25972222 | AU26: 0.26041667 | AV26: 25 | AW26: 0.34513889 | AX26: 0.34652778
B27: 611 | C27: 49 | D27: 0.26111111 | E27: 0.26180556 | F27: 50 | G27: 0.31388889 | H27: 0.31388889 | I27: 44 | J27: 0.37361111 | K27: 0.37847222 | L27: 41 | M27: 0.45 | N27: 0.45277778 | O27: 41 | P27: 0.5125 | Q27: 0.51527778 | R27: 38 | S27: 0.57013889 | T27: 0.57083333 | U27: 32 | V27: 0.60694444 | W27: 0.61736111 | X27: 33 | Z27: 0.71388889 | AA27: 34 | AB27: 0.77013889 | AC27: 0.77291667 | AD27: 34 | AE27: 0.86111111 | AF27: 0.87569444 | AG27: 37 | AH27: 0.94652778 | AI27: 0.95 | AJ27: 37 | AK27: 0.047222222 | AL27: 0.052777778 | AM27: 31 | AN27: 0.10763889 | AO27: 0.12361111 | AP27: 33 | AQ27: 0.19513889 | AR27: 0.19930556 | AS27: 31 | AT27: 0.29513889 | AU27: 0.29930556 | AV27: 26 | AW27: 0.35555556 | AX27: 0.35555556
B28: 692 | C28: 45 | D28: 0.26111111 | E28: 0.26180556 | F28: 48 | G28: 0.31388889 | H28: 0.31388889 | I28: 53 | J28: 0.37638889 | K28: 0.38055556 | L28: 56 | M28: 0.46180556 | N28: 0.46527778 | O28: 62 | P28: 0.53333333 | Q28: 0.53541667 | R28: 62 | S28: 0.6 | T28: 0.60347222 | U28: 61 | V28: 0.64513889 | W28: 0.65416667 | X28: 59 | Z28: 0.75694444 | AA28: 57 | AB28: 0.8125 | AC28: 0.81527778 | AD28: 48 | AE28: 0.89513889 | AF28: 0.90763889 | AG28: 42 | AH28: 0.97152778 | AI28: 0.97777778 | AJ28: 38 | AK28: 0.059027778 | AL28: 0.065277778 | AM28: 34 | AN28: 0.11527778 | AO28: 0.11875 | AP28: 30 | AQ28: 0.18888889 | AR28: 0.19444444 | AS28: 28 | AT28: 0.29166667 | AU28: 0.29444444 | AV28: 27 | AW28: 0.35625 | AX28: 0.35625
B29: 697 | C29: 34 | D29: 0.25972222 | E29: 0.26041667 | F29: 28 | G29: 0.30694444 | H29: 0.30694444 | I29: 21 | J29: 0.36319444 | K29: 0.36388889 | L29: 15 | M29: 0.42986111 | N29: 0.43263889 | O29: 13 | P29: 0.48680556 | Q29: 0.48888889 | R29: 14 | S29: 0.54444444 | T29: 0.54722222 | U29: 14 | V29: 0.5875 | W29: 0.59513889 | X29: 14 | Z29: 0.68541667 | AA29: 16 | AB29: 0.74305556 | AC29: 0.74583333 | AD29: 24 | AE29: 0.83055556 | AF29: 0.84097222 | AG29: 23 | AH29: 0.90555556 | AI29: 0.90902778 | AJ29: 22 | AK29: 0.99652778 | AL29: 0.0027777778 | AM29: 23 | AN29: 0.070138889 | AO29: 0.075 | AP29: 23 | AQ29: 0.14722222 | AR29: 0.15208333 | AS29: 26 | AT29: 0.26805556 | AU29: 0.27986111 | AV29: 28 | AW29: 0.36180556 | AX29: 0.35694444
B30: 715 | I30: 48 | J30: 0.375 | K30: 0.37916667 | L30: 44 | M30: 0.45277778 | N30: 0.45486111 | O30: 44 | P30: 0.5125 | Q30: 0.51527778 | R30: 42 | S30: 0.57152778 | T30: 0.57291667 | U30: 39 | V30: 0.61180556 | W30: 0.61944444 | X30: 34 | Z30: 0.71388889 | AA30: 33 | AB30: 0.77013889 | AC30: 0.77291667 | AD30: 33 | AE30: 0.86041667 | AF30: 0.87222222 | AG30: 32 | AH30: 0.93958333 | AI30: 0.94236111 | AJ30: 32 | AK30: 0.035416667 | AL30: 0.038194444 | AM30: 29 | AN30: 0.099305556 | AO30: 0.11597222 | AP30: 29 | AQ30: 0.18680556 | AR30: 0.19166667 | AS30: 29 | AT30: 0.29305556 | AU30: 0.29722222 | AV30: 29 | AW30: 0.36527778 | AX30: 0.36597222
B31: 686 | C31: 43 | D31: 0.26041667 | E31: 0.26180556 | F31: 49 | G31: 0.31388889 | H31: 0.31388889 | I31: 55 | J31: 0.37708333 | K31: 0.37986111 | L31: 51 | M31: 0.45902778 | N31: 0.46041667 | O31: 53 | P31: 0.52291667 | Q31: 0.52569444 | R31: 55 | S31: 0.58888889 | T31: 0.59097222 | U31: 53 | V31: 0.63333333 | W31: 0.63611111 | X31: 44 | Z31: 0.72847222 | AA31: 42 | AB31: 0.78541667 | AC31: 0.7875 | AD31: 38 | AE31: 0.87152778 | AF31: 0.87569444 | AG31: 34 | AH31: 0.94166667 | AI31: 0.94513889 | AJ31: 28 | AK31: 0.03125 | AL31: 0.032638889 | AM31: 27 | AN31: 0.088888889 | AO31: 0.092361111 | AP31: 27 | AQ31: 0.16319444 | AR31: 0.16597222 | AS31: 27 | AT31: 0.27638889 | AU31: 0.27986111 | AV31: 30 | AW31: 0.36805556 | AX31: 0.36180556
B32: 729 | C32: 67 | D32: 0.26388889 | E32: 0.26458333 | F32: 71 | G32: 0.32083333 | H32: 0.32083333 | I32: 63 | J32: 0.38402778 | K32: 0.38611111 | L32: 62 | M32: 0.46527778 | N32: 0.46666667 | O32: 59 | P32: 0.52916667 | Q32: 0.53055556 | R32: 53 | S32: 0.58819444 | T32: 0.58958333 | U32: 48 | V32: 0.62916667 | W32: 0.63125 | X32: 45 | Z32: 0.73194444 | AA32: 45 | AB32: 0.79027778 | AC32: 0.79236111 | AD32: 39 | AE32: 0.87708333 | AF32: 0.88333333 | AG32: 39 | AH32: 0.95763889 | AI32: 0.96180556 | AJ32: 39 | AK32: 0.0625 | AL32: 0.065972222 | AM32: 35 | AN32: 0.12152778 | AO32: 0.12777778 | AP32: 34 | AQ32: 0.19722222 | AR32: 0.20069444 | AS32: 30 | AT32: 0.29305556 | AU32: 0.29722222 | AV32: 31 | AW32: 0.37708333 | AX32: 0.37986111
B33: 550 | C33: 76 | D33: 0.26597222 | E33: 0.26666667 | I33: 82 | J33: 0.38819444 | K33: 0.39652778 | L33: 81 | M33: 0.47847222 | N33: 0.48055556 | O33: 76 | P33: 0.54513889 | Q33: 0.55416667 | R33: 78 | S33: 0.61666667 | T33: 0.61944444 | U33: 70 | V33: 0.6625 | W33: 0.67083333 | X33: 65 | Z33: 0.77013889 | AA33: 62 | AB33: 0.82222222 | AC33: 0.82361111 | AD33: 56 | AE33: 0.91388889 | AF33: 0.925 | AG33: 51 | AH33: 0.99791667 | AI33: 0.0034722222 | AJ33: 53 | AK33: 0.10555556 | AL33: 0.10763889 | AM33: 42 | AN33: 0.15416667 | AO33: 0.16041667 | AP33: 45 | AQ33: 0.23958333 | AR33: 0.24583333 | AS33: 41 | AT33: 0.32777778 | AU33: 0.32777778 | AV33: 32 | AW33: 0.38263889 | AX33: 0.38263889
B34: 527 | C34: 23 | D34: 0.25763889 | E34: 0.25833333 | F34: 20 | G34: 0.30625 | H34: 0.30625 | I34: 18 | J34: 0.3625 | K34: 0.36388889 | L34: 18 | M34: 0.43472222 | N34: 0.43611111 | O34: 19 | P34: 0.49444444 | Q34: 0.49583333 | R34: 21 | S34: 0.55416667 | T34: 0.55763889 | U34: 22 | V34: 0.59930556 | W34: 0.61111111 | X34: 30 | Z34: 0.70416667 | AA34: 31 | AB34: 0.76805556 | AC34: 0.77152778 | AD34: 32 | AE34: 0.85972222 | AF34: 0.87708333 | AG34: 35 | AH34: 0.94513889 | AI34: 0.94861111 | AJ34: 35 | AK34: 0.041666667 | AL34: 0.046527778 | AM34: 33 | AN34: 0.11111111 | AO34: 0.12152778 | AP34: 32 | AQ34: 0.19513889 | AR34: 0.20069444 | AS34: 35 | AT34: 0.31180556 | AU34: 0.31527778 | AV34: 33 | AW34: 0.38263889 | AX34: 0.38263889
B35: 530 | C35: 46 | D35: 0.26111111 | E35: 0.26180556 | F35: 40 | G35: 0.31319444 | H35: 0.31319444 | I35: 57 | J35: 0.37847222 | K35: 0.38055556 | L35: 49 | M35: 0.45694444 | N35: 0.45902778 | O35: 49 | P35: 0.52083333 | Q35: 0.52291667 | R35: 51 | S35: 0.5875 | T35: 0.58888889 | U35: 49 | V35: 0.63055556 | W35: 0.63402778 | X35: 48 | Z35: 0.73888889 | AA35: 49 | AB35: 0.8 | AC35: 0.80208333 | AD35: 50 | AE35: 0.90138889 | AF35: 0.91805556 | AG35: 47 | AH35: 0.99097222 | AI35: 0.99305556 | AJ35: 41 | AK35: 0.074305556 | AL35: 0.075694444 | AM35: 38 | AN35: 0.13472222 | AO35: 0.14305556 | AP35: 37 | AQ35: 0.2125 | AR35: 0.21736111 | AS35: 34 | AT35: 0.31041667 | AU35: 0.31180556 | AV35: 34 | AW35: 0.38263889 | AX35: 0.38333333
B36: 684 | C36: 121 | D36: 0.27013889 | E36: 0.27083333 | F36: 102 | G36: 0.32569444 | H36: 0.32569444 | I36: 66 | J36: 0.38541667 | K36: 0.3875 | L36: 53 | M36: 0.45972222 | N36: 0.46111111 | O36: 47 | P36: 0.51805556 | Q36: 0.52361111 | R36: 47 | S36: 0.58263889 | T36: 0.58541667 | U36: 46 | V36: 0.62361111 | W36: 0.6375 | X36: 42 | Z36: 0.72638889 | AA36: 36 | AB36: 0.77569444 | AC36: 0.78125 | AD36: 35 | AE36: 0.86458333 | AF36: 0.88333333 | AG36: 36 | AH36: 0.94513889 | AI36: 0.94930556 | AJ36: 31 | AK36: 0.034722222 | AL36: 0.038888889 | AM36: 28 | AN36: 0.097222222 | AO36: 0.11805556 | AP36: 28 | AQ36: 0.18055556 | AR36: 0.1875 | AS36: 32 | AT36: 0.29791667 | AU36: 0.30277778 | AV36: 35 | AW36: 0.38611111 | AX36: 0.38611111
B37: 507 | C37: 44 | D37: 0.26111111 | E37: 0.26180556 | F37: 32 | G37: 0.30763889 | H37: 0.30763889 | I37: 41 | J37: 0.37152778 | K37: 0.37847222 | L37: 52 | M37: 0.45972222 | N37: 0.46111111 | O37: 50 | P37: 0.52152778 | Q37: 0.525 | R37: 49 | S37: 0.58541667 | T37: 0.58819444 | U37: 47 | V37: 0.62777778 | W37: 0.63263889 | X37: 46 | Z37: 0.73333333 | AA37: 46 | AB37: 0.79375 | AC37: 0.8 | AD37: 45 | AE37: 0.88958333 | AF37: 0.90069444 | AG37: 41 | AH37: 0.97083333 | AI37: 0.97777778 | AJ37: 40 | AK37: 0.072916667 | AL37: 0.080555556 | AM37: 36 | AN37: 0.12986111 | AO37: 0.14305556 | AP37: 36 | AQ37: 0.21180556 | AR37: 0.21527778 | AS37: 36 | AT37: 0.31388889 | AU37: 0.31944444 | AV37: 36 | AW37: 0.39444444 | AX37: 0.39652778
B38: 645 | C38: 56 | D38: 0.26319444 | E38: 0.26388889 | F38: 72 | G38: 0.32083333 | H38: 0.32083333 | I38: 72 | J38: 0.38680556 | K38: 0.38958333 | L38: 61 | M38: 0.46458333 | N38: 0.46597222 | O38: 54 | P38: 0.525 | Q38: 0.52777778 | R38: 50 | S38: 0.5875 | T38: 0.59027778 | U38: 52 | V38: 0.63125 | W38: 0.64166667 | X38: 47 | Z38: 0.73402778 | AA38: 44 | AB38: 0.79027778 | AC38: 0.79375 | AD38: 40 | AE38: 0.87708333 | AF38: 0.88958333 | AG38: 38 | AH38: 0.94930556 | AI38: 0.95694444 | AJ38: 36 | AK38: 0.045138889 | AL38: 0.050694444 | AM38: 32 | AN38: 0.10902778 | AO38: 0.13333333 | AP38: 35 | AQ38: 0.2 | AR38: 0.20763889 | AS38: 33 | AT38: 0.30763889 | AU38: 0.32222222 | AV38: 37 | AW38: 0.39583333 | AX38: 0.39791667
B39: 511 | C39: 37 | D39: 0.26041667 | E39: 0.26180556 | F39: 22 | G39: 0.30625 | H39: 0.30625 | I39: 27 | J39: 0.36597222 | K39: 0.37013889 | L39: 36 | M39: 0.44652778 | N39: 0.44791667 | O39: 45 | P39: 0.51319444 | Q39: 0.51527778 | R39: 46 | S39: 0.57986111 | T39: 0.58125 | U39: 45 | V39: 0.62222222 | W39: 0.63194444 | X39: 50 | Z39: 0.74375 | AA39: 50 | AB39: 0.80277778 | AC39: 0.80763889 | AD39: 46 | AE39: 0.89166667 | AF39: 0.91111111 | AG39: 43 | AH39: 0.98055556 | AI39: 0.98680556 | AJ39: 42 | AK39: 0.076388889 | AL39: 0.080555556 | AM39: 37 | AN39: 0.13333333 | AO39: 0.15138889 | AP39: 38 | AQ39: 0.21458333 | AR39: 0.22152778 | AS39: 37 | AT39: 0.31666667 | AU39: 0.32638889 | AV39: 38 | AW39: 0.39791667 | AX39: 0.39930556
